[34m[1mwandb[0m: [32m[41mERROR[0m Attempted to change value of key "data_dir" from /content/drive/My Drive/LONDON_DATASET to /scratches/mario/hw501/satellite-cGAN/../data_source/LONDON_DATASET
[34m[1mwandb[0m: [32m[41mERROR[0m If you really want to do this, pass allow_val_change=True to config.update()
Traceback (most recent call last):
  File "train_cGAN.py", line 118, in <module>
    config.data_dir = DATA_DIR
  File "/scratch/hw501/anaconda3/envs/satellite/lib/python3.8/site-packages/wandb/wandb_config.py", line 249, in __setitem__
    key, val = self._sanitize(key, val)
  File "/scratch/hw501/anaconda3/envs/satellite/lib/python3.8/site-packages/wandb/wandb_config.py", line 264, in _sanitize
    raise ConfigError('Attempted to change value of key "{}" from {} to {}\nIf you really want to do this, pass allow_val_change=True to config.update()'.format(
wandb.wandb_config.ConfigError: Attempted to change value of key "data_dir" from /content/drive/My Drive/LONDON_DATASET to /scratches/mario/hw501/satellite-cGAN/../data_source/LONDON_DATASET
If you really want to do this, pass allow_val_change=True to config.update()
